ERROR:root:<urlopen error [WinError 10060] A connection attempt failed because the connected party did not properly respond after a period of time, or established connection failed because connected host has failed to respond>
Traceback (most recent call last):
  File "C:\Users\shohan\anaconda3\lib\urllib\request.py", line 1319, in do_open
    encode_chunked=req.has_header('Transfer-encoding'))
  File "C:\Users\shohan\anaconda3\lib\http\client.py", line 1252, in request
    self._send_request(method, url, body, headers, encode_chunked)
  File "C:\Users\shohan\anaconda3\lib\http\client.py", line 1298, in _send_request
    self.endheaders(body, encode_chunked=encode_chunked)
  File "C:\Users\shohan\anaconda3\lib\http\client.py", line 1247, in endheaders
    self._send_output(message_body, encode_chunked=encode_chunked)
  File "C:\Users\shohan\anaconda3\lib\http\client.py", line 1026, in _send_output
    self.send(msg)
  File "C:\Users\shohan\anaconda3\lib\http\client.py", line 966, in send
    self.connect()
  File "C:\Users\shohan\anaconda3\lib\http\client.py", line 1414, in connect
    super().connect()
  File "C:\Users\shohan\anaconda3\lib\http\client.py", line 938, in connect
    (self.host,self.port), self.timeout, self.source_address)
  File "C:\Users\shohan\anaconda3\lib\socket.py", line 728, in create_connection
    raise err
  File "C:\Users\shohan\anaconda3\lib\socket.py", line 716, in create_connection
    sock.connect(sa)
TimeoutError: [WinError 10060] A connection attempt failed because the connected party did not properly respond after a period of time, or established connection failed because connected host has failed to respond

During handling of the above exception, another exception occurred:

Traceback (most recent call last):
  File "c:\Users\shohan\Desktop\Python Web Scrapping\wscrap.py", line 24, in retrive_webpage
    html = urlopen(Request(url,data=None, headers=header))
  File "C:\Users\shohan\anaconda3\lib\urllib\request.py", line 222, in urlopen
    return opener.open(url, data, timeout)
  File "C:\Users\shohan\anaconda3\lib\urllib\request.py", line 525, in open
    response = self._open(req, data)
  File "C:\Users\shohan\anaconda3\lib\urllib\request.py", line 543, in _open
    '_open', req)
  File "C:\Users\shohan\anaconda3\lib\urllib\request.py", line 503, in _call_chain
    result = func(*args)
  File "C:\Users\shohan\anaconda3\lib\urllib\request.py", line 1362, in https_open
    context=self._context, check_hostname=self._check_hostname)
  File "C:\Users\shohan\anaconda3\lib\urllib\request.py", line 1321, in do_open
    raise URLError(err)
urllib.error.URLError: <urlopen error [WinError 10060] A connection attempt failed because the connected party did not properly respond after a period of time, or established connection failed because connected host has failed to respond>
ERROR:root:a bytes-like object is required, not 'str'
Traceback (most recent call last):
  File "c:\Users\shohan\Desktop\Python Web Scrapping\wscrap.py", line 40, in write_webpage_as_html
    fobj.write(self.__data)
TypeError: a bytes-like object is required, not 'str'
